Workbook

Sheet Summary
A1: COPART, INC. (NASDAQ: CPRT) - LONG | HFAC x Citadel 2026 Stock Pitch | Valuation model summary
A3: Recommendation | B3: LONG
A4: Current price (24-Sep-2026) | B4: =Inputs!$B$6
A5: 12-month probability-weighted target | B5: =Valuation!$B$32
A6: Expected return | B6: =Valuation!$B$33
A7: Bear / Base / Bull target | B7: =TEXT(Valuation!B25,"$0.00")&" / "&TEXT(Valuation!C25,"$0.00")&" / "&TEXT(Valuation!D25,"$0.00")
A8: Bear / Base / Bull return | B8: =TEXT(Valuation!B26,"0%")&" / "&TEXT(Valuation!C26,"0%")&" / "&TEXT(Valuation!D26,"0%")
A9: Probabilities (Bear/Base/Bull) | B9: =TEXT(Inputs!B21,"0%")&" / "&TEXT(Inputs!C21,"0%")&" / "&TEXT(Inputs!D21,"0%")
A10: Market cap ($M) | B10: =Inputs!$B$12
A11: Enterprise value ($M) | B11: =Inputs!$B$13
A12: Current NTM P/E (consensus FY27E $1.63) | B12: =Inputs!$B$6/1.63
A13: Current EV / FY26A EBITDA | B13: =Inputs!$B$13/1882
A14: DCF value per share (active scenario) | B14: =DCF!B21
A15: Active scenario | B15: =Inputs!C17
A17: Sheet guide
A18: Inputs - all assumptions (blue), scenario selector (B17), probabilities, ACV deal terms, DCF inputs
A19: Historical - FY21-FY26 financials (Capital IQ export) and CapIQ multiple history
A20: Model - 5-year operating model for the ACTIVE scenario incl. ACV consolidation, buybacks, cash
A21: Scenarios - Bear / Base / Bull models side by side (feeds Valuation)
A22: Valuation - 12-month target price via P/E & EV/EBITDA per scenario, probability-weighted, P/E x EPS sensitivity
A23: DCF - 5-yr DCF on active scenario, WACC x g sensitivity
A24: Comps - RBA / KAR / CPRT history and implied values
A25: ACV Deal - deal multiples, synergy breakeven, EPS accretion/dilution sensitivity
A26: Sources: Copart FY26 press release & 10-K, Capital IQ export (provided), ACV/Copart merger press release (10-Sep-2026), Undiscovered Compounders deep dives (provided), public quotes 24-Sep-2026.

Sheet Inputs
A1: COPART (CPRT) - MODEL INPUTS | blue = hard-coded input, black = formula, green = link
A2: All $ in millions except per share. Fiscal year ends July 31.
A4: Market data & capitalization
A5: Valuation date | B5: 2026-09-25 | H5: Memo date
A6: Share price ($) | B6: 28.04 | H6: NASDAQ close 24-Sep-2026
A7: Basic shares outstanding (M) | B7: 925.811 | H7: CapIQ, latest (post FY26 buybacks)
A8: FY26 diluted weighted shares (M) | B8: 956.86 | H8: FY26 10-K / CapIQ
A9: Cash & HTM/short-term investments | B9: 4489.8 | H9: Balance sheet 31-Jul-2026
A10: Total debt (leases; no funded debt) | B10: 88.4 | H10: Balance sheet 31-Jul-2026
A11: Minority interest | B11: 16.6 | H11: Balance sheet 31-Jul-2026
A12: Market capitalization | B12: =B6*B7 | H12: formula
A13: Enterprise value | B13: =B12-B9+B10+B11 | H13: formula
A14: Target horizon (months) | B14: 12 | H14: Competition: 3-12 month horizon
A16: Scenario selector (drives 'Model' and 'DCF' sheets)
A17: Active scenario (1 = Bear, 2 = Base, 3 = Bull) | B17: 2 | C17: =CHOOSE(B17,"Bear","Base","Bull")
A19: Operating assumptions by scenario
B20: Bear | C20: Base | D20: Bull | H20: Rationale / source
A21: Scenario probability | B21: 0.25 | C21: 0.5 | D21: 0.25 | E21: =SUM(B21:D21) | H21: Must sum to 100%; base weighted to reflect Q4-26 assignment data
A22: US unit growth | B22: FY27E | C22: FY28E | D22: FY29E | E22: FY30E | F22: FY31E | H22: Q4-26 US insurance assignments +2.3% ex-one lost customer (Progressive); Q1-27 still down MSD, growth returns by Q4-27 (base)
A23: Bear | B23: -0.03 | C23: -0.01 | D23: 0 | E23: 0 | F23: 0
A24: Base | B24: -0.01 | C24: 0.03 | D24: 0.025 | E24: 0.025 | F24: 0.025
A25: Bull | B25: 0.01 | C25: 0.045 | D25: 0.04 | E25: 0.04 | F25: 0.04
A26: Active (per selector) | B26: =CHOOSE(Inputs!$B$17,B23,B24,B25) | C26: =CHOOSE(Inputs!$B$17,C23,C24,C25) | D26: =CHOOSE(Inputs!$B$17,D23,D24,D25) | E26: =CHOOSE(Inputs!$B$17,E23,E24,E25) | F26: =CHOOSE(Inputs!$B$17,F23,F24,F25)
A28: International unit growth | B28: FY27E | C28: FY28E | D28: FY29E | E28: FY30E | F28: FY31E | H28: Q4-26 intl units +10%, intl insurance +11.2%; FY26 intl revenue +8.5%; ex-FX mid/high-single digits
A29: Bear | B29: 0.025 | C29: 0.025 | D29: 0.025 | E29: 0.025 | F29: 0.025
A30: Base | B30: 0.055 | C30: 0.055 | D30: 0.055 | E30: 0.055 | F30: 0.055
A31: Bull | B31: 0.08 | C31: 0.08 | D31: 0.08 | E31: 0.08 | F31: 0.08
A32: Active (per selector) | B32: =CHOOSE(Inputs!$B$17,B29,B30,B31) | C32: =CHOOSE(Inputs!$B$17,C29,C30,C31) | D32: =CHOOSE(Inputs!$B$17,D29,D30,D31) | E32: =CHOOSE(Inputs!$B$17,E29,E30,E31) | F32: =CHOOSE(Inputs!$B$17,F29,F30,F31)
A34: Revenue per unit (RPU) growth | B34: FY27E | C34: FY28E | D34: FY29E | E34: FY30E | F34: FY31E | H34: FY26 RPU +5.7%; rising ASP & total-loss frequency (23.3% record CQ2-26), Title Express/long-haul fees. Bear = used-car deflation
A35: Bear | B35: 0.01 | C35: -0.01 | D35: -0.01 | E35: 0 | F35: 0
A36: Base | B36: 0.035 | C36: 0.035 | D36: 0.035 | E36: 0.035 | F36: 0.035
A37: Bull | B37: 0.055 | C37: 0.055 | D37: 0.05 | E37: 0.05 | F37: 0.05
A38: Active (per selector) | B38: =CHOOSE(Inputs!$B$17,B35,B36,B37) | C38: =CHOOSE(Inputs!$B$17,C35,C36,C37) | D38: =CHOOSE(Inputs!$B$17,D35,D36,D37) | E38: =CHOOSE(Inputs!$B$17,E35,E36,E37) | F38: =CHOOSE(Inputs!$B$17,F35,F36,F37)
A40: Core EBIT margin (ex-ACV) | B40: FY27E | C40: FY28E | D40: FY29E | E40: FY30E | F40: FY31E | H40: FY26 35.4% (FY25 37.7%). Operating leverage on fixed land base reverses when units grow; ~1pt of unit growth = ~$31M EBIT (deep dive)
A41: Bear | B41: 0.335 | C41: 0.325 | D41: 0.32 | E41: 0.32 | F41: 0.32
A42: Base | B42: 0.35 | C42: 0.36 | D42: 0.365 | E42: 0.37 | F42: 0.37
A43: Bull | B43: 0.36 | C43: 0.375 | D43: 0.385 | E43: 0.39 | F43: 0.39
A44: Active (per selector) | B44: =CHOOSE(Inputs!$B$17,B41,B42,B43) | C44: =CHOOSE(Inputs!$B$17,C41,C42,C43) | D44: =CHOOSE(Inputs!$B$17,D41,D42,D43) | E44: =CHOOSE(Inputs!$B$17,E41,E42,E43) | F44: =CHOOSE(Inputs!$B$17,F41,F42,F43)
A46: D&A % revenue (ex-ACV) | B46: FY27E | C46: FY28E | D46: FY29E | E46: FY30E | F46: FY31E | H46: FY26 $229M = 4.9% of revenue
A47: Bear | B47: 0.05 | C47: 0.05 | D47: 0.05 | E47: 0.05 | F47: 0.05
...

Sheet Historical
A1: HISTORICAL FINANCIALS (S&P Capital IQ export; FY ends Jul-31; $M)
B3: FY21A | C3: FY22A | D3: FY23A | E3: FY24A | F3: FY25A | G3: FY26A
A4: Total revenue | B4: 2692.5 | C4: 3500.9 | D4: 3869.5 | E4: 4236.8 | F4: 4647 | G4: 4666.2
A5: US revenue | B5: 2272.1 | C5: 2945.2 | D5: 3189.6 | E5: 3464.7 | F5: 3855.1 | G5: 3807.4
A6: International revenue | B6: 420.4 | C6: 555.8 | D6: 679.9 | E6: 772.1 | F6: 791.9 | G6: 858.8
A7: Service revenue | F7: 3968.7 | G7: 3969.5
A8: Vehicle sales | F8: 678.3 | G8: 696.7
A9: Gross profit (co. definition) | B9: 1343.1 | C9: 1606.2 | D9: 1737 | E9: 1939.2 | F9: 2099.6 | G9: 2083.9
A10: Operating income (EBIT) | B10: 1136.4 | C10: 1375 | D10: 1486.6 | E10: 1573.2 | F10: 1752.7 | G10: 1652.6
A11: US EBIT | B11: 1023.6 | C11: 1247.6 | D11: 1368.1 | E11: 1428 | F11: 1480.9 | G11: 1419
A12: International EBIT | B12: 112.9 | C12: 127.4 | D12: 118.5 | E12: 144 | F12: 215.8 | G12: 233.6
A13: D&A | B13: 112.4 | C13: 128.8 | D13: 152.3 | E13: 181.1 | F13: 202.8 | G13: 229.4
A14: EBITDA | B14: 1248.8 | C14: 1503.8 | D14: 1638.9 | E14: 1754.3 | F14: 1955.5 | G14: 1882
A15: Interest & investment income (net) | B15: -20.2 | C15: -16.7 | D15: 65.9 | E15: 145.7 | F15: 178.9 | G15: 181.9
A16: Pre-tax income | B16: 1121.8 | C16: 1341 | D16: 1554.3 | E16: 1714.6 | F16: 1895.6 | G16: 1835
A17: Income tax | B17: 185.4 | C17: 250.8 | D17: 316.6 | E17: 352.3 | F17: 347.2 | G17: 354.6
A18: Net income | B18: 936.5 | C18: 1090.1 | D18: 1237.7 | E18: 1363 | F18: 1552.4 | G18: 1484.3
A19: Diluted EPS ($) | B19: 0.97 | C19: 1.13 | D19: 1.28 | E19: 1.4 | F19: 1.59 | G19: 1.55
A20: Diluted shares (M) | B20: 961.2 | C20: 964.6 | D20: 966.6 | E20: 974.8 | F20: 977.6 | G20: 956.9
... A25: Total debt (leases) | B25: 518.1 | C25: 119.5 | D25: 120.5 | E25: 118.7 | F25: 103.7 | G25: 88.4
A26: Land (at cost) | B26: 1428.3 | C26: 1526.4 | D26: 1812 | E26: 2027.6 | F26: 2394.6
A28: Derived ratios
A29: Revenue growth | C29: =IF(B4="","",C4/B4-1) | D29: =IF(C4="","",D4/C4-1) | E29: =IF(D4="","",E4/D4-1) | F29: =IF(E4="","",F4/E4-1) | G29: =IF(F4="","",G4/F4-1)
A30: EBIT margin | B30: =B10/B4 | C30: =C10/C4 | D30: =D10/D4 | E30: =E10/E4 | F30: =F10/F4 | G30: =G10/G4
A31: EBITDA margin | B31: =B14/B4 | C31: =C14/C4 | D31: =D14/D4 | E31: =E14/E4 | F31: =F14/F4 | G31: =G14/G4
A32: Free cash flow (CFO - capex) | B32: =B21+B22 | C32: =C21+C22 | D32: =D21+D22 | E32: =E21+E22 | F32: =F21+F22 | G32: =G21+G22
A33: FCF margin | B33: =(B21+B22)/B4 | C33: =(C21+C22)/C4 | D33: =(D21+D22)/D4 | E33: =(E21+E22)/E4 | F33: =(F21+F22)/F4 | G33: =(G21+G22)/G4
A34: Capex % revenue | B34: =-B22/B4 | C34: =-C22/C4 | D34: =-D22/D4 | E34: =-E22/E4 | F34: =-F22/F4 | G34: =-G22/G4
A35: International % revenue | B35: =B6/B4 | C35: =C6/C4 | D35: =D6/D4 | E35: =E6/E4 | F35: =F6/F4 | G35: =G6/G4
A36: Effective tax rate | B36: =B17/B16 | C36: =C17/C16 | D36: =D17/D16 | E36: =E17/E16 | F36: =F17/F16 | G36: =G17/G16
A38: Valuation history (CapIQ, quarterly averages of daily multiples)
B39: CQ4-24 | C39: CQ1-25 | D39: CQ2-25 | E39: CQ3-25 | F39: CQ4-25 | G39: CQ1-26 | H39: CQ2-26 | I39: CQ3-26*
A40: TEV / NTM EBITDA (avg) | B40: 25.8 | C40: 24.5 | D40: 23.8 | E40: 19.6 | F40: 17 | G40: 15.4 | H40: 13 | I40: 11.9 | J40: =AVERAGE(B40:I40) | K40: 2-yr avg
A41: P / NTM EPS (avg) | B41: 36.1 | C41: 34.5 | D41: 33.7 | E41: 28.4 | F41: 24.6 | G41: 22.9 | H41: 20 | I41: 18.5 | J41: =AVERAGE(B41:I41) | K41: 2-yr avg
A42: TEV / NTM revenue (avg) | B42: 11 | C42: 10.5 | D42: 10.2 | E42: 8.4 | F42: 7.3 | G42: 6.6 | H42: 5.5 | I42: 5 | J42: =AVERAGE(B42:I42) | K42: 2-yr avg
A43: * quarter-to-date through 24-Sep-2026. Source: Capital IQ 'Multiples' tab of provided export.

Sheet Model
A1: OPERATING MODEL - ACTIVE SCENARIO (change Inputs!B17) | $M, FY ends Jul-31 | H1: =CHOOSE(Inputs!$B$17,"BEAR","BASE","BULL")
B2: FY26A | C2: FY27E | D2: FY28E | E2: FY29E | F2: FY30E | G2: FY31E
A3: Core Copart (ex-ACV)
A4: US revenue | B4: 3807.4 | C4: =B4*(1+Inputs!$B$26)*(1+Inputs!$B$38) | D4: =C4*(1+Inputs!$C$26)*(1+Inputs!$C$38) | E4: =D4*(1+Inputs!$D$26)*(1+Inputs!$D$38) | F4: =E4*(1+Inputs!$E$26)*(1+Inputs!$E$38) | G4: =F4*(1+Inputs!$F$26)*(1+Inputs!$F$38)
A5: International revenue | B5: 858.8 | C5: =B5*(1+Inputs!$B$32)*(1+Inputs!$B$38) | D5: =C5*(1+Inputs!$C$32)*(1+Inputs!$C$38) | E5: =D5*(1+Inputs!$D$32)*(1+Inputs!$D$38) | F5: =E5*(1+Inputs!$E$32)*(1+Inputs!$E$38) | G5: =F5*(1+Inputs!$F$32)*(1+Inputs!$F$38)
A6: Core revenue | B6: =B4+B5 | C6: =C4+C5 | D6: =D4+D5 | E6: =E4+E5 | F6: =F4+F5 | G6: =G4+G5
A7: growth | C7: =C6/B6-1 | D7: =D6/C6-1 | E7: =E6/D6-1 | F7: =F6/E6-1 | G7: =G6/F6-1
A8: Core EBIT margin | B8: =B9/B6 | C8: =Inputs!$B$44 | D8: =Inputs!$C$44 | E8: =Inputs!$D$44 | F8: =Inputs!$E$44 | G8: =Inputs!$F$44
A9: Core EBIT | B9: 1652.6 | C9: =C6*C8 | D9: =D6*D8 | E9: =E6*E8 | F9: =F6*F8 | G9: =G6*G8
A10: Core D&A | B10: 229.4 | C10: =C6*Inputs!$B$50 | D10: =D6*Inputs!$C$50 | E10: =E6*Inputs!$D$50 | F10: =F6*Inputs!$E$50 | G10: =G6*Inputs!$F$50
A11: Core capex | B11: 337.4 | C11: =C6*Inputs!$B$56 | D11: =D6*Inputs!$C$56 | E11: =E6*Inputs!$D$56 | F11: =F6*Inputs!$E$56 | G11: =G6*Inputs!$F$56
A12: ACV Auctions (consolidated from close; CY figures used as FY proxy)
A13: Consolidation factor (share of year) | B13: 0 | C13: =Inputs!$B$118/12 | D13: =1 | E13: =1 | F13: =1 | G13: =1
A14: ACV revenue (annualized run-rate) | C14: =Inputs!$B$119*(1+Inputs!$B$104) | D14: =C14*(1+Inputs!$C$104) | E14: =D14*(1+Inputs!$D$104) | F14: =E14*(1+Inputs!$E$104) | G14: =F14*(1+Inputs!$F$104)
A15: ACV revenue consolidated | B15: 0 | C15: =C14*C13 | D15: =D14*D13 | E15: =E14*E13 | F15: =F14*F13 | G15: =G14*G13
A16: ACV adj. EBITDA (standalone) | C16: =C15*Inputs!$B$110 | D16: =D15*Inputs!$C$110 | E16: =E15*Inputs!$D$110 | F16: =F15*Inputs!$E$110 | G16: =G15*Inputs!$F$110
A17: less: ACV SBC | C17: =-Inputs!$B$120*(1+Inputs!$B$125)^1*C13 | D17: =-Inputs!$B$120*(1+Inputs!$B$125)^2*D13 | E17: =-Inputs!$B$120*(1+Inputs!$B$125)^3*E13 | F17: =-Inputs!$B$120*(1+Inputs!$B$125)^4*F13 | G17: =-Inputs!$B$120*(1+Inputs!$B$125)^5*G13
A18: less: ACV existing D&A | C18: =-Inputs!$B$121*(1+Inputs!$B$125)^1*C13 | D18: =-Inputs!$B$121*(1+Inputs!$B$125)^2*D13 | E18: =-Inputs!$B$121*(1+Inputs!$B$125)^3*E13 | F18: =-Inputs!$B$121*(1+Inputs!$B$125)^4*F13 | G18: =-Inputs!$B$121*(1+Inputs!$B$125)^5*G13
A19: less: acquired-intangible amortization | C19: =-Inputs!$B$124*C13 | D19: =-Inputs!$B$124*D13 | E19: =-Inputs!$B$124*E13 | F19: =-Inputs!$B$124*F13 | G19: =-Inputs!$B$124*G13
A20: plus: synergies (pre-tax) | C20: =Inputs!$B$98 | D20: =Inputs!$C$98 | E20: =Inputs!$D$98 | F20: =Inputs!$E$98 | G20: =Inputs!$F$98
A21: ACV EBIT contribution (GAAP) | B21: 0 | C21: =SUM(C16:C20) | D21: =SUM(D16:D20) | E21: =SUM(E16:E20) | F21: =SUM(F16:F20) | G21: =SUM(G16:G20)
A22: ACV D&A (total) | B22: 0 | C22: =-C18-C19 | D22: =-D18-D19 | E22: =-E18-E19 | F22: =-F18-F19 | G22: =-G18-G19
A23: ACV capex | B23: 0 | C23: =C15*0.02 | D23: =D15*0.02 | E23: =E15*0.02 | F23: =F15*0.02 | G23: =G15*0.02
A24: Consolidated P&L
A25: Total revenue | B25: =B6 | C25: =C6+C15 | D25: =D6+D15 | E25: =E6+E15 | F25: =F6+F15 | G25: =G6+G15
A26: growth | C26: =C25/B25-1 | D26: =D25/C25-1 | E26: =E25/D25-1 | F26: =F25/E25-1 | G26: =G25/F25-1
A27: EBIT | B27: =B9 | C27: =C9+C21 | D27: =D9+D21 | E27: =E9+E21 | F27: =F9+F21 | G27: =G9+G21
A28: EBIT margin | B28: =B27/B25 | C28: =C27/C25 | D28: =D27/D25 | E28: =E27/E25 | F28: =F27/F25 | G28: =G27/G25
A29: D&A | B29: =B10 | C29: =C10+C22 | D29: =D10+D22 | E29: =E10+E22 | F29: =F10+F22 | G29: =G10+G22
A30: EBITDA | B30: =B27+B29 | C30: =C27+C29 | D30: =D27+D29 | E30: =E27+E29 | F30: =F27+F29 | G30: =G27+G29
A31: Interest income on cash | B31: 181.9 | C31: =(B44+C42+C43)*Inputs!$B$74 | D31: =(C44+D42+D43)*Inputs!$C$74 | E31: =(D44+E42+E43)*Inputs!$D$74 | F31: =(E44+F42+F43)*Inputs!$E$74 | G31: =(F44+G42+G43)*Inputs!$F$74 | I31: On beginning cash less buybacks & ACV outlay (avoids circularity)
A32: Pre-tax income | B32: 1835 | C32: =C27+C31 | D32: =D27+D31 | E32: =E27+E31 | F32: =F27+F31 | G32: =G27+G31
A33: Tax | B33: -354.6 | C33: =-C32*Inputs!$B$68 | D33: =-D32*Inputs!$C$68 | E33: =-E32*Inputs!$D$68 | F33: =-F32*Inputs!$E$68 | G33: =-G32*Inputs!$F$68
A34: Net income | B34: 1484.3 | C34: =C32+C33 | D34: =D32+D33 | E34: =E32+E33 | F34: =F32+F33 | G34: =G32+G33
A35: Diluted shares (M, avg) | B35: 956.86 | C35: =AVERAGE(B46,C46) | D35: =AVERAGE(C46,D46) | E35: =AVERAGE(D46,E46) | F35: =AVERAGE(E46,F46) | G35: =AVERAGE(F46,G46)
A36: Diluted EPS ($) | B36: 1.55 | C36: =C34/C35 | D36: =D34/D35 | E36: =E34/E35 | F36: =F34/F35 | G36: =G34/G35
A37: EPS growth | C37: =C36/B36-1 | D37: =D36/C36-1 | E37: =E36/D36-1 | F37: =F36/E36-1 | G37: =G36/F36-1
A38: Cash EPS (ex acquired-intangible amort., $) | B38: 1.55 | C38: =(C34-C19*(1-Inputs!$B$68))/C35 | D38: =(D34-D19*(1-Inputs!$C$68))/D35 | E38: =(E34-E19*(1-Inputs!$D$68))/E35 | F38: =(F34-F19*(1-Inputs!$E$68))/F35 | G38: =(G34-G19*(1-Inputs!$F$68))/G35
A39: Cash flow & share count
A40: Unlevered FCF (EBIT*(1-t) + D&A - capex - dNWC) | C40: =C27*(1-Inputs!$B$68)+C29-C11-C23-(C25-B25)*Inputs!$B$62 | D40: =D27*(1-Inputs!$C$68)+D29-D11-D23-(D25-C25)*Inputs!$C$62 | E40: =E27*(1-Inputs!$D$68)+E29-E11-E23-(E25-D25)*Inputs!$D$62 | F40: =F27*(1-Inputs!$E$68)+F29-F11-F23-(F25-E25)*Inputs!$E$62 | G40: =G27*(1-Inputs!$F$68)+G29-G11-G23-(G25-F25)*Inputs!$F$62
...

Sheet Scenarios
A1: BEAR CASE - full model
B2: FY26A | C2: FY27E | D2: FY28E | E2: FY29E | F2: FY30E | G2: FY31E
A3: Core Copart (ex-ACV)
A4: US revenue | B4: 3807.4 | C4: =B4*(1+Inputs!$B$23)*(1+Inputs!$B$35) | D4: =C4*(1+Inputs!$C$23)*(1+Inputs!$C$35) | E4: =D4*(1+Inputs!$D$23)*(1+Inputs!$D$35) | F4: =E4*(1+Inputs!$E$23)*(1+Inputs!$E$35) | G4: =F4*(1+Inputs!$F$23)*(1+Inputs!$F$35)
A5: International revenue | B5: 858.8 | C5: =B5*(1+Inputs!$B$29)*(1+Inputs!$B$35) | D5: =C5*(1+Inputs!$C$29)*(1+Inputs!$C$35) | E5: =D5*(1+Inputs!$D$29)*(1+Inputs!$D$35) | F5: =E5*(1+Inputs!$E$29)*(1+Inputs!$E$35) | G5: =F5*(1+Inputs!$F$29)*(1+Inputs!$F$35)
A6: Core revenue | B6: =B4+B5 | C6: =C4+C5 | D6: =D4+D5 | E6: =E4+E5 | F6: =F4+F5 | G6: =G4+G5
A7: growth | C7: =C6/B6-1 | D7: =D6/C6-1 | E7: =E6/D6-1 | F7: =F6/E6-1 | G7: =G6/F6-1
A8: Core EBIT margin | B8: =B9/B6 | C8: =Inputs!$B$41 | D8: =Inputs!$C$41 | E8: =Inputs!$D$41 | F8: =Inputs!$E$41 | G8: =Inputs!$F$41
A9: Core EBIT | B9: 1652.6 | C9: =C6*C8 | D9: =D6*D8 | E9: =E6*E8 | F9: =F6*F8 | G9: =G6*G8
A10: Core D&A | B10: 229.4 | C10: =C6*Inputs!$B$47 | D10: =D6*Inputs!$C$47 | E10: =E6*Inputs!$D$47 | F10: =F6*Inputs!$E$47 | G10: =G6*Inputs!$F$47
A11: Core capex | B11: 337.4 | C11: =C6*Inputs!$B$53 | D11: =D6*Inputs!$C$53 | E11: =E6*Inputs!$D$53 | F11: =F6*Inputs!$E$53 | G11: =G6*Inputs!$F$53
A12: ACV Auctions (consolidated from close; CY figures used as FY proxy)
A13: Consolidation factor (share of year) | B13: 0 | C13: =Inputs!$B$118/12 | D13: =1 | E13: =1 | F13: =1 | G13: =1
A14: ACV revenue (annualized run-rate) | C14: =Inputs!$B$119*(1+Inputs!$B$101) | D14: =C14*(1+Inputs!$C$101) | E14: =D14*(1+Inputs!$D$101) | F14: =E14*(1+Inputs!$E$101) | G14: =F14*(1+Inputs!$F$101)
A15: ACV revenue consolidated | B15: 0 | C15: =C14*C13 | D15: =D14*D13 | E15: =E14*E13 | F15: =F14*F13 | G15: =G14*G13
A16: ACV adj. EBITDA (standalone) | C16: =C15*Inputs!$B$107 | D16: =D15*Inputs!$C$107 | E16: =E15*Inputs!$D$107 | F16: =F15*Inputs!$E$107 | G16: =G15*Inputs!$F$107
A17: less: ACV SBC | C17: =-Inputs!$B$120*(1+Inputs!$B$125)^1*C13 | D17: =-Inputs!$B$120*(1+Inputs!$B$125)^2*D13 | E17: =-Inputs!$B$120*(1+Inputs!$B$125)^3*E13 | F17: =-Inputs!$B$120*(1+Inputs!$B$125)^4*F13 | G17: =-Inputs!$B$120*(1+Inputs!$B$125)^5*G13
A18: less: ACV existing D&A | C18: =-Inputs!$B$121*(1+Inputs!$B$125)^1*C13 | D18: =-Inputs!$B$121*(1+Inputs!$B$125)^2*D13 | E18: =-Inputs!$B$121*(1+Inputs!$B$125)^3*E13 | F18: =-Inputs!$B$121*(1+Inputs!$B$125)^4*F13 | G18: =-Inputs!$B$121*(1+Inputs!$B$125)^5*G13
A19: less: acquired-intangible amortization | C19: =-Inputs!$B$124*C13 | D19: =-Inputs!$B$124*D13 | E19: =-Inputs!$B$124*E13 | F19: =-Inputs!$B$124*F13 | G19: =-Inputs!$B$124*G13
A20: plus: synergies (pre-tax) | C20: =Inputs!$B$95 | D20: =Inputs!$C$95 | E20: =Inputs!$D$95 | F20: =Inputs!$E$95 | G20: =Inputs!$F$95
A21: ACV EBIT contribution (GAAP) | B21: 0 | C21: =SUM(C16:C20) | D21: =SUM(D16:D20) | E21: =SUM(E16:E20) | F21: =SUM(F16:F20) | G21: =SUM(G16:G20)
A22: ACV D&A (total) | B22: 0 | C22: =-C18-C19 | D22: =-D18-D19 | E22: =-E18-E19 | F22: =-F18-F19 | G22: =-G18-G19
A23: ACV capex | B23: 0 | C23: =C15*0.02 | D23: =D15*0.02 | E23: =E15*0.02 | F23: =F15*0.02 | G23: =G15*0.02
A24: Consolidated P&L
A25: Total revenue | B25: =B6 | C25: =C6+C15 | D25: =D6+D15 | E25: =E6+E15 | F25: =F6+F15 | G25: =G6+G15
A26: growth | C26: =C25/B25-1 | D26: =D25/C25-1 | E26: =E25/D25-1 | F26: =F25/E25-1 | G26: =G25/F25-1
A27: EBIT | B27: =B9 | C27: =C9+C21 | D27: =D9+D21 | E27: =E9+E21 | F27: =F9+F21 | G27: =G9+G21
A28: EBIT margin | B28: =B27/B25 | C28: =C27/C25 | D28: =D27/D25 | E28: =E27/E25 | F28: =F27/F25 | G28: =G27/G25
A29: D&A | B29: =B10 | C29: =C10+C22 | D29: =D10+D22 | E29: =E10+E22 | F29: =F10+F22 | G29: =G10+G22
A30: EBITDA | B30: =B27+B29 | C30: =C27+C29 | D30: =D27+D29 | E30: =E27+E29 | F30: =F27+F29 | G30: =G27+G29
A31: Interest income on cash | B31: 181.9 | C31: =(B44+C42+C43)*Inputs!$B$71 | D31: =(C44+D42+D43)*Inputs!$C$71 | E31: =(D44+E42+E43)*Inputs!$D$71 | F31: =(E44+F42+F43)*Inputs!$E$71 | G31: =(F44+G42+G43)*Inputs!$F$71 | I31: On beginning cash less buybacks & ACV outlay (avoids circularity)
A32: Pre-tax income | B32: 1835 | C32: =C27+C31 | D32: =D27+D31 | E32: =E27+E31 | F32: =F27+F31 | G32: =G27+G31
A33: Tax | B33: -354.6 | C33: =-C32*Inputs!$B$65 | D33: =-D32*Inputs!$C$65 | E33: =-E32*Inputs!$D$65 | F33: =-F32*Inputs!$E$65 | G33: =-G32*Inputs!$F$65
A34: Net income | B34: 1484.3 | C34: =C32+C33 | D34: =D32+D33 | E34: =E32+E33 | F34: =F32+F33 | G34: =G32+G33
A35: Diluted shares (M, avg) | B35: 956.86 | C35: =AVERAGE(B46,C46) | D35: =AVERAGE(C46,D46) | E35: =AVERAGE(D46,E46) | F35: =AVERAGE(E46,F46) | G35: =AVERAGE(F46,G46)
A36: Diluted EPS ($) | B36: 1.55 | C36: =C34/C35 | D36: =D34/D35 | E36: =E34/E35 | F36: =F34/F35 | G36: =G34/G35
A37: EPS growth | C37: =C36/B36-1 | D37: =D36/C36-1 | E37: =E36/D36-1 | F37: =F36/E36-1 | G37: =G36/F36-1
A38: Cash EPS (ex acquired-intangible amort., $) | B38: 1.55 | C38: =(C34-C19*(1-Inputs!$B$65))/C35 | D38: =(D34-D19*(1-Inputs!$C$65))/D35 | E38: =(E34-E19*(1-Inputs!$D$65))/E35 | F38: =(F34-F19*(1-Inputs!$E$65))/F35 | G38: =(G34-G19*(1-Inputs!$F$65))/G35
A39: Cash flow & share count
A40: Unlevered FCF (EBIT*(1-t) + D&A - capex - dNWC) | C40: =C27*(1-Inputs!$B$65)+C29-C11-C23-(C25-B25)*Inputs!$B$59 | D40: =D27*(1-Inputs!$C$65)+D29-D11-D23-(D25-C25)*Inputs!$C$59 | E40: =E27*(1-Inputs!$D$65)+E29-E11-E23-(E25-D25)*Inputs!$D$59 | F40: =F27*(1-Inputs!$E$65)+F29-F11-F23-(F25-E25)*Inputs!$E$59 | G40: =G27*(1-Inputs!$F$65)+G29-G11-G23-(G25-F25)*Inputs!$F$59
...

Sheet Valuation
A1: 12-MONTH TARGET PRICE - SCENARIO ANALYSIS (target date ~Sep-2027; NTM = FY28E)
B2: Bear | C2: Base | D2: Bull | E2: Prob-wtd | F2: Notes
A3: Probability | B3: =Inputs!B$21 | C3: =Inputs!C$21 | D3: =Inputs!D$21 | E3: =SUM(B3:D3)
A4: Operating outputs
A5: FY27E revenue | B5: =Scenarios!$C$25 | C5: =Scenarios!$C$72 | D5: =Scenarios!$C$119 | E5: =SUMPRODUCT(B5:D5,Inputs!$B$21:$D$21) | F5: Consensus FY27E $4,914M (CapIQ)
A6: FY28E revenue | B6: =Scenarios!$D$25 | C6: =Scenarios!$D$72 | D6: =Scenarios!$D$119 | E6: =SUMPRODUCT(B6:D6,Inputs!$B$21:$D$21) | F6: Consensus FY28E $5,306M (CapIQ)
A7: FY27E EPS | B7: =Scenarios!$C$36 | C7: =Scenarios!$C$83 | D7: =Scenarios!$C$130 | E7: =SUMPRODUCT(B7:D7,Inputs!$B$21:$D$21) | F7: Consensus FY27E $1.63
A8: FY28E EPS (NTM at target date) | B8: =Scenarios!$D$36 | C8: =Scenarios!$D$83 | D8: =Scenarios!$D$130 | E8: =SUMPRODUCT(B8:D8,Inputs!$B$21:$D$21) | F8: Consensus FY28E $1.77
A9: FY28E cash EPS (ex deal amortization) | B9: =Scenarios!$D$38 | C9: =Scenarios!$D$85 | D9: =Scenarios!$D$132 | E9: =SUMPRODUCT(B9:D9,Inputs!$B$21:$D$21)
A10: FY28E EBITDA | B10: =Scenarios!$D$30 | C10: =Scenarios!$D$77 | D10: =Scenarios!$D$124 | E10: =SUMPRODUCT(B10:D10,Inputs!$B$21:$D$21)
A11: FY27E ending net cash | B11: =Scenarios!$C$44-Inputs!$B$10-Inputs!$B$11 | C11: =Scenarios!$C$91-Inputs!$B$10-Inputs!$B$11 | D11: =Scenarios!$C$138-Inputs!$B$10-Inputs!$B$11 | E11: =SUMPRODUCT(B11:D11,Inputs!$B$21:$D$21) | F11: Post-ACV cash, post-buybacks
A12: FY27E ending diluted shares (M) | B12: =Scenarios!$C$46 | C12: =Scenarios!$C$93 | D12: =Scenarios!$C$140 | E12: =SUMPRODUCT(B12:D12,Inputs!$B$21:$D$21)
A13: Method 1: P/E on NTM EPS
A14: Target P/E | B14: =Inputs!$B$112 | C14: =Inputs!$C$112 | D14: =Inputs!$D$112 | F14: Current 17.7x NTM; 2-yr avg 27x
A15: Implied price (P/E) | B15: =B14*B8 | C15: =C14*C8 | D15: =D14*D8 | E15: =SUMPRODUCT(B15:D15,Inputs!$B$21:$D$21)
A16: Method 2: EV/EBITDA on NTM EBITDA
A17: Target EV/EBITDA | B17: =Inputs!$B$113 | C17: =Inputs!$C$113 | D17: =Inputs!$D$113 | F17: Current 11.3x NTM; 2-yr avg 18.9x
A18: Implied EV | B18: =B17*B10 | C18: =C17*C10 | D18: =D17*D10
A19: Implied equity value | B19: =B18+B11 | C19: =C18+C11 | D19: =D18+D11
A20: Implied price (EV/EBITDA) | B20: =B19/B12 | C20: =C19/C12 | D20: =D19/D12 | E20: =SUMPRODUCT(B20:D20,Inputs!$B$21:$D$21)
A21: Method 3: DCF (intrinsic, from DCF sheet - active scenario only)
A22: DCF value per share (active scenario) | B22: =IF(Inputs!$B$17=1,DCF!$B$30,"n/a - set selector") | C22: =IF(Inputs!$B$17=2,DCF!$B$30,"n/a - set selector") | D22: =IF(Inputs!$B$17=3,DCF!$B$30,"n/a - set selector") | F22: Run each scenario via Inputs!B17 to populate
A23: Blended 12-month target
A24: Weight: P/E method | B24: 0.5 | F24: Remaining weight to EV/EBITDA
A25: 12-month target price | B25: =$B$24*B15+(1-$B$24)*B20 | C25: =$B$24*C15+(1-$B$24)*C20 | D25: =$B$24*D15+(1-$B$24)*D20 | E25: =SUMPRODUCT(B25:D25,Inputs!$B$21:$D$21)
A26: Upside / (downside) vs current | B26: =B25/Inputs!$B$6-1 | C26: =C25/Inputs!$B$6-1 | D26: =D25/Inputs!$B$6-1 | E26: =E25/Inputs!$B$6-1
A27: Implied NTM P/E at target (check) | B27: =B25/B8 | C27: =C25/C8 | D27: =D25/D8
A28: Implied EV/NTM EBITDA at target (check) | B28: =(B25*B12-B11)/B10 | C28: =(C25*C12-C11)/C10 | D28: =(D25*D12-D11)/D10
A30: Risk / reward
A31: Current price | B31: =Inputs!$B$6
A32: Probability-weighted target | B32: =E25
A33: Probability-weighted expected return | B33: =E26
A34: Upside (bull) / downside (bear) ratio | B34: =(D25-Inputs!$B$6)/(Inputs!$B$6-B25)
A35: Current NTM P/E (FY27E consensus EPS $1.63) | B35: =Inputs!$B$6/1.63
A36: Current EV / FY26A EBITDA | B36: =Inputs!$B$13/1882
A38: Sensitivity: 12-month price = Target P/E x FY28E EPS
A39: FY28E EPS -> | B39: 1.45 | C39: 1.55 | D39: 1.65 | E39: 1.75 | F39: 1.85 | G39: 1.95
A40: 14 | B40: =$A40*B$39 | C40: =$A40*C$39 | D40: =$A40*D$39 | E40: =$A40*E$39 | F40: =$A40*F$39 | G40: =$A40*G$39
A41: 16 | B41: =$A41*B$39 | C41: =$A41*C$39 | D41: =$A41*D$39 | E41: =$A41*E$39 | F41: =$A41*F$39 | G41: =$A41*G$39
A42: 18 | B42: =$A42*B$39 | C42: =$A42*C$39 | D42: =$A42*D$39 | E42: =$A42*E$39 | F42: =$A42*F$39 | G42: =$A42*G$39
...

Sheet DCF
A1: DCF - ACTIVE SCENARIO (5-yr explicit, Gordon growth terminal) | $M | H1: =CHOOSE(Inputs!$B$17,"BEAR","BASE","BULL")
B3: FY27E | C3: FY28E | D3: FY29E | E3: FY30E | F3: FY31E
A4: Unlevered FCF | B4: =Model!C40 | C4: =Model!D40 | D4: =Model!E40 | E4: =Model!F40 | F4: =Model!G40
A5: Discount period (yrs) | B5: =1-0.5*Inputs!$B$136 | C5: =2-0.5*Inputs!$B$136 | D5: =3-0.5*Inputs!$B$136 | E5: =4-0.5*Inputs!$B$136 | F5: =5-0.5*Inputs!$B$136
A6: Discount factor | B6: =1/(1+Inputs!$B$134)^B5 | C6: =1/(1+Inputs!$B$134)^C5 | D6: =1/(1+Inputs!$B$134)^D5 | E6: =1/(1+Inputs!$B$134)^E5 | F6: =1/(1+Inputs!$B$134)^F5
A7: PV of FCF | B7: =B4*B6 | C7: =C4*C6 | D7: =D4*D6 | E7: =E4*E6 | F7: =F4*F6
A9: WACC | B9: =Inputs!$B$134
A10: Terminal growth | B10: =Inputs!$B$135
A11: Terminal value (FY31 FCF x (1+g) / (WACC-g)) | B11: =F4*(1+B10)/(B9-B10)
A12: PV of terminal value | B12: =B11*F6
A13: Sum PV of FCF (FY27-31) | B13: =SUM(B7:F7)
A14: Enterprise value | B14: =B12+B13
A15: % of EV from terminal value | B15: =B12/B14
A16: Plus: cash & investments (31-Jul-26) | B16: =Inputs!$B$9
A17: Less: ACV purchase price (cash out at close) | B17: =-Inputs!$B$116
A18: Less: debt & minority interest | B18: =-Inputs!$B$10-Inputs!$B$11
A19: Equity value | B19: =SUM(B14,B16:B18)
A20: Diluted shares today (M) | B20: =Model!B46
A21: DCF value per share ($) | B21: =B19/B20
A22: Upside vs current | B22: =B21/Inputs!$B$6-1
A23: Implied EV / FY27E EBITDA | B23: =B14/Model!C30
A24: Implied terminal EV / FY31 EBITDA | B24: =B11/Model!G30
A30: DCF value per share (link) | B30: =B21
A32: Sensitivity: DCF value per share vs WACC (rows) and terminal growth (cols)
A33: WACC \ g | B33: 0.02 | C33: 0.025 | D33: 0.03 | E33: 0.035 | F33: 0.04
A34: 0.075 | B34: =(B$4/(1+$A34)^B$5+C$4/(1+$A34)^C$5+D$4/(1+$A34)^D$5+E$4/(1+$A34)^E$5+F$4/(1+$A34)^F$5+F$4*(1+B$33)/($A34-B$33)/(1+$A34)^F$5+$B$16+$B$17+$B$18)/$B$20 | C34: =(B$4/(1+$A34)^B$5+C$4/(1+$A34)^C$5+D$4/(1+$A34)^D$5+E$4/(1+$A34)^E$5+F$4/(1+$A34)^F$5+F$4*(1+C$33)/($A34-C$33)/(1+$A34)^F$5+$B$16+$B$17+$B$18)/$B$20 | D34: =(B$4/(1+$A34)^B$5+C$4/(1+$A34)^C$5+D$4/(1+$A34)^D$5+E$4/(1+$A34)^E$5+F$4/(1+$A34)^F$5+F$4*(1+D$33)/($A34-D$33)/(1+$A34)^F$5+$B$16+$B$17+$B$18)/$B$20 | E34: =(B$4/(1+$A34)^B$5+C$4/(1+$A34)^C$5+D$4/(1+$A34)^D$5+E$4/(1+$A34)^E$5+F$4/(1+$A34)^F$5+F$4*(1+E$33)/($A34-E$33)/(1+$A34)^F$5+$B$16+$B$17+$B$18)/$B$20 | F34: =(B$4/(1+$A34)^B$5+C$4/(1+$A34)^C$5+D$4/(1+$A34)^D$5+E$4/(1+$A34)^E$5+F$4/(1+$A34)^F$5+F$4*(1+F$33)/($A34-F$33)/(1+$A34)^F$5+$B$16+$B$17+$B$18)/$B$20
A35: 0.08 | B35: =(B$4/(1+$A35)^B$5+C$4/(1+$A35)^C$5+D$4/(1+$A35)^D$5+E$4/(1+$A35)^E$5+F$4/(1+$A35)^F$5+F$4*(1+B$33)/($A35-B$33)/(1+$A35)^F$5+$B$16+$B$17+$B$18)/$B$20 | C35: =(B$4/(1+$A35)^B$5+C$4/(1+$A35)^C$5+D$4/(1+$A35)^D$5+E$4/(1+$A35)^E$5+F$4/(1+$A35)^F$5+F$4*(1+C$33)/($A35-C$33)/(1+$A35)^F$5+$B$16+$B$17+$B$18)/$B$20 | D35: =(B$4/(1+$A35)^B$5+C$4/(1+$A35)^C$5+D$4/(1+$A35)^D$5+E$4/(1+$A35)^E$5+F$4/(1+$A35)^F$5+F$4*(1+D$33)/($A35-D$33)/(1+$A35)^F$5+$B$16+$B$17+$B$18)/$B$20 | E35: =(B$4/(1+$A35)^B$5+C$4/(1+$A35)^C$5+D$4/(1+$A35)^D$5+E$4/(1+$A35)^E$5+F$4/(1+$A35)^F$5+F$4*(1+E$33)/($A35-E$33)/(1+$A35)^F$5+$B$16+$B$17+$B$18)/$B$20 | F35: =(B$4/(1+$A35)^B$5+C$4/(1+$A35)^C$5+D$4/(1+$A35)^D$5+E$4/(1+$A35)^E$5+F$4/(1+$A35)^F$5+F$4*(1+F$33)/($A35-F$33)/(1+$A35)^F$5+$B$16+$B$17+$B$18)/$B$20
A36: 0.085 | B36: =(B$4/(1+$A36)^B$5+C$4/(1+$A36)^C$5+D$4/(1+$A36)^D$5+E$4/(1+$A36)^E$5+F$4/(1+$A36)^F$5+F$4*(1+B$33)/($A36-B$33)/(1+$A36)^F$5+$B$16+$B$17+$B$18)/$B$20 | C36: =(B$4/(1+$A36)^B$5+C$4/(1+$A36)^C$5+D$4/(1+$A36)^D$5+E$4/(1+$A36)^E$5+F$4/(1+$A36)^F$5+F$4*(1+C$33)/($A36-C$33)/(1+$A36)^F$5+$B$16+$B$17+$B$18)/$B$20 | D36: =(B$4/(1+$A36)^B$5+C$4/(1+$A36)^C$5+D$4/(1+$A36)^D$5+E$4/(1+$A36)^E$5+F$4/(1+$A36)^F$5+F$4*(1+D$33)/($A36-D$33)/(1+$A36)^F$5+$B$16+$B$17+$B$18)/$B$20 | E36: =(B$4/(1+$A36)^B$5+C$4/(1+$A36)^C$5+D$4/(1+$A36)^D$5+E$4/(1+$A36)^E$5+F$4/(1+$A36)^F$5+F$4*(1+E$33)/($A36-E$33)/(1+$A36)^F$5+$B$16+$B$17+$B$18)/$B$20 | F36: =(B$4/(1+$A36)^B$5+C$4/(1+$A36)^C$5+D$4/(1+$A36)^D$5+E$4/(1+$A36)^E$5+F$4/(1+$A36)^F$5+F$4*(1+F$33)/($A36-F$33)/(1+$A36)^F$5+$B$16+$B$17+$B$18)/$B$20
A37: 0.09 | B37: =(B$4/(1+$A37)^B$5+C$4/(1+$A37)^C$5+D$4/(1+$A37)^D$5+E$4/(1+$A37)^E$5+F$4/(1+$A37)^F$5+F$4*(1+B$33)/($A37-B$33)/(1+$A37)^F$5+$B$16+$B$17+$B$18)/$B$20 | C37: =(B$4/(1+$A37)^B$5+C$4/(1+$A37)^C$5+D$4/(1+$A37)^D$5+E$4/(1+$A37)^E$5+F$4/(1+$A37)^F$5+F$4*(1+C$33)/($A37-C$33)/(1+$A37)^F$5+$B$16+$B$17+$B$18)/$B$20 | D37: =(B$4/(1+$A37)^B$5+C$4/(1+$A37)^C$5+D$4/(1+$A37)^D$5+E$4/(1+$A37)^E$5+F$4/(1+$A37)^F$5+F$4*(1+D$33)/($A37-D$33)/(1+$A37)^F$5+$B$16+$B$17+$B$18)/$B$20 | E37: =(B$4/(1+$A37)^B$5+C$4/(1+$A37)^C$5+D$4/(1+$A37)^D$5+E$4/(1+$A37)^E$5+F$4/(1+$A37)^F$5+F$4*(1+E$33)/($A37-E$33)/(1+$A37)^F$5+$B$16+$B$17+$B$18)/$B$20 | F37: =(B$4/(1+$A37)^B$5+C$4/(1+$A37)^C$5+D$4/(1+$A37)^D$5+E$4/(1+$A37)^E$5+F$4/(1+$A37)^F$5+F$4*(1+F$33)/($A37-F$33)/(1+$A37)^F$5+$B$16+$B$17+$B$18)/$B$20
A38: 0.095 | B38: =(B$4/(1+$A38)^B$5+C$4/(1+$A38)^C$5+D$4/(1+$A38)^D$5+E$4/(1+$A38)^E$5+F$4/(1+$A38)^F$5+F$4*(1+B$33)/($A38-B$33)/(1+$A38)^F$5+$B$16+$B$17+$B$18)/$B$20 | C38: =(B$4/(1+$A38)^B$5+C$4/(1+$A38)^C$5+D$4/(1+$A38)^D$5+E$4/(1+$A38)^E$5+F$4/(1+$A38)^F$5+F$4*(1+C$33)/($A38-C$33)/(1+$A38)^F$5+$B$16+$B$17+$B$18)/$B$20 | D38: =(B$4/(1+$A38)^B$5+C$4/(1+$A38)^C$5+D$4/(1+$A38)^D$5+E$4/(1+$A38)^E$5+F$4/(1+$A38)^F$5+F$4*(1+D$33)/($A38-D$33)/(1+$A38)^F$5+$B$16+$B$17+$B$18)/$B$20 | E38: =(B$4/(1+$A38)^B$5+C$4/(1+$A38)^C$5+D$4/(1+$A38)^D$5+E$4/(1+$A38)^E$5+F$4/(1+$A38)^F$5+F$4*(1+E$33)/($A38-E$33)/(1+$A38)^F$5+$B$16+$B$17+$B$18)/$B$20 | F38: =(B$4/(1+$A38)^B$5+C$4/(1+$A38)^C$5+D$4/(1+$A38)^D$5+E$4/(1+$A38)^E$5+F$4/(1+$A38)^F$5+F$4*(1+F$33)/($A38-F$33)/(1+$A38)^F$5+$B$16+$B$17+$B$18)/$B$20
A39: 0.1 | B39: =(B$4/(1+$A39)^B$5+C$4/(1+$A39)^C$5+D$4/(1+$A39)^D$5+E$4/(1+$A39)^E$5+F$4/(1+$A39)^F$5+F$4*(1+B$33)/($A39-B$33)/(1+$A39)^F$5+$B$16+$B$17+$B$18)/$B$20 | C39: =(B$4/(1+$A39)^B$5+C$4/(1+$A39)^C$5+D$4/(1+$A39)^D$5+E$4/(1+$A39)^E$5+F$4/(1+$A39)^F$5+F$4*(1+C$33)/($A39-C$33)/(1+$A39)^F$5+$B$16+$B$17+$B$18)/$B$20 | D39: =(B$4/(1+$A39)^B$5+C$4/(1+$A39)^C$5+D$4/(1+$A39)^D$5+E$4/(1+$A39)^E$5+F$4/(1+$A39)^F$5+F$4*(1+D$33)/($A39-D$33)/(1+$A39)^F$5+$B$16+$B$17+$B$18)/$B$20 | E39: =(B$4/(1+$A39)^B$5+C$4/(1+$A39)^C$5+D$4/(1+$A39)^D$5+E$4/(1+$A39)^E$5+F$4/(1+$A39)^F$5+F$4*(1+E$33)/($A39-E$33)/(1+$A39)^F$5+$B$16+$B$17+$B$18)/$B$20 | F39: =(B$4/(1+$A39)^B$5+C$4/(1+$A39)^C$5+D$4/(1+$A39)^D$5+E$4/(1+$A39)^E$5+F$4/(1+$A39)^F$5+F$4*(1+F$33)/($A39-F$33)/(1+$A39)^F$5+$B$16+$B$17+$B$18)/$B$20

Sheet Comps
A1: COMPARABLE COMPANIES & CPRT HISTORY (approx. public data as of 24-Sep-2026; verify before submission)
A3: Company | B3: Ticker | C3: EV ($B) | D3: EV/EBITDA (LTM) | E3: EV/EBITDA (NTM) | F3: P/E (NTM) | G3: EBIT margin | H3: Net debt/EBITDA | I3: Comment
A4: RB Global (owns IAA) | B4: RBA | C4: 19.3 | D4: 14.8 | E4: 13 | F4: 17.9 | G4: 0.17 | H4: 1.5 | I4: Direct salvage competitor via IAA; levered; margins ~half of CPRT; StockAnalysis/Finviz
A5: OPENLANE | B5: KAR | C5: 2.9 | D5: 10 | E5: 8.5 | F5: 20 | G5: 0.1 | H5: 0.5 | I5: Digital dealer wholesale (closest ACV comp); Reuters/TickerSpark
A6: Copart - current | B6: CPRT | C6: =Inputs!$B$13/1000 | D6: =Inputs!$B$13/1882 | E6: 11.3 | F6: 17.7 | G6: 0.354 | H6: -2.3 | I6: CapIQ export; net cash
A7: Copart - 2-yr avg (CQ4-24 to CQ3-26) | B7: CPRT | E7: =Historical!$J$40 | F7: =Historical!$J$41 | G7: 0.37 | I7: CapIQ Multiples tab
A8: Copart - CQ4-2024 avg | B8: CPRT | E8: 25.8 | F8: 36.1 | G8: 0.377 | I8: Pre-derating level
A10: Peer median (RBA, KAR) | D10: =MEDIAN(D4:D5) | E10: =MEDIAN(E4:E5) | F10: =MEDIAN(F4:F5)
A12: Implied CPRT value at peer / historical multiples (on FY27E base-case figures)
A13: Basis | B13: Multiple | C13: Metric ($M / $) | D13: Implied EV | E13: Implied equity | F13: Per share | G13: vs current
A14: Peer median EV/NTM EBITDA | B14: =E10 | C14: =Scenarios!$C$77 | D14: =B14*C14 | E14: =D14+(Inputs!$B$9-Inputs!$B$116-Inputs!$B$10-Inputs!$B$11) | F14: =E14/Inputs!$B$7 | G14: =F14/Inputs!$B$6-1
A15: RBA EV/NTM EBITDA | B15: =E4 | C15: =Scenarios!$C$77 | D15: =B15*C15 | E15: =D15+(Inputs!$B$9-Inputs!$B$116-Inputs!$B$10-Inputs!$B$11) | F15: =E15/Inputs!$B$7 | G15: =F15/Inputs!$B$6-1
A16: CPRT 2-yr avg EV/NTM EBITDA | B16: =E7 | C16: =Scenarios!$C$77 | D16: =B16*C16 | E16: =D16+(Inputs!$B$9-Inputs!$B$116-Inputs!$B$10-Inputs!$B$11) | F16: =E16/Inputs!$B$7 | G16: =F16/Inputs!$B$6-1
A17: Peer median NTM P/E | B17: =F10 | C17: =Scenarios!$C$83 | F17: =B17*C17 | G17: =F17/Inputs!$B$6-1
A18: CPRT 2-yr avg NTM P/E | B18: =F7 | C18: =Scenarios!$C$83 | F18: =B18*C18 | G18: =F18/Inputs!$B$6-1
A20: Read-across: CPRT trades at a discount to RBA (IAA's parent) on P/E despite ~2x the EBIT margin, zero debt and $4.5B cash. The market is pricing structural share loss; the data (assignments +2.3% ex one customer) says cyclical.

Sheet ACV Deal
A1: ACV AUCTIONS ACQUISITION - DEAL MATH & ACCRETION (base case)
A3: Purchase price ($M) | B3: =Inputs!$B$116 | F3: Cash tender at $10.50/sh
A4: ACV CY25 revenue | B4: 760 | F4: ACV 10-K
A5: ACV CY25 adj. EBITDA | B5: 59
A6: ACV CY26E revenue (guide) | B6: =Inputs!$B$119
A7: ACV CY26E adj. EBITDA (guide mid) | B7: 75 | F7: $73-77M
A8: EV / CY25 revenue | B8: =B3/B4
A9: EV / CY25 adj. EBITDA | B9: =B3/B5
A10: EV / CY26E adj. EBITDA | B10: =B3/B7
A11: Foregone interest on cash (pre-tax, $M/yr) | B11: =B3*Inputs!$B$72 | F11: Cost of funding the deal from cash
A12: Deal amortization (pre-tax, $M/yr) | B12: =Inputs!$B$124 | F12: Non-cash
A13: Pre-tax synergies required for GAAP EPS breakeven (FY28, ex-amort.) | B13: =B11-Scenarios!D63-Scenarios!D64-Scenarios!D65 | F13: Foregone interest less ACV standalone EBIT (ex deal amort.)
A14: Base-case FY28 synergies assumed | B14: =Inputs!$C$96
A15: FY28E GAAP EPS impact of ACV (base, $) | B15: =(Scenarios!D68-B11)*(1-0.195)/Scenarios!D82 | F15: Includes deal amortization and foregone interest
A16: FY28E cash EPS impact of ACV (base, $) | B16: =(Scenarios!D68-Scenarios!D66-B11)*(1-0.195)/Scenarios!D82 | F16: Ex deal amortization
A17: Strategic logic | B17: Franchise-dealer access CPRT never cracked organically (20 yrs); 829k ACV units onto 21k acres/281 yards; buyer cross-sell; floorplan; vs. buyback at ~18x P/E = ~5.5% earnings yield
A19: Synergy sensitivity: FY28E GAAP EPS impact vs pre-tax synergies ($M)
A20: Synergies -> | B20: 0 | C20: 25 | D20: 50 | E20: 75 | F20: 100 | G20: 150
A21: FY28E GAAP EPS impact ($) | B21: =(Scenarios!$D$68-Scenarios!$D$67+B20-$B$11)*(1-0.195)/Scenarios!$D$82 | C21: =(Scenarios!$D$68-Scenarios!$D$67+C20-$B$11)*(1-0.195)/Scenarios!$D$82 | D21: =(Scenarios!$D$68-Scenarios!$D$67+D20-$B$11)*(1-0.195)/Scenarios!$D$82 | E21: =(Scenarios!$D$68-Scenarios!$D$67+E20-$B$11)*(1-0.195)/Scenarios!$D$82 | F21: =(Scenarios!$D$68-Scenarios!$D$67+F20-$B$11)*(1-0.195)/Scenarios!$D$82 | G21: =(Scenarios!$D$68-Scenarios!$D$67+G20-$B$11)*(1-0.195)/Scenarios!$D$82
